Workbook

Sheet Back-Test Log
A1: PSL DECISION ENGINE — BACK-TEST LOG | PSL 2025 Season | Fill YELLOW cells with real match results
A2: MATCH INFO | F2: SYSTEM RECOMMENDATION (pre-filled) | K2: ACTUAL RESULT ← fill these in yellow | P2: KEY MOMENTS ← fill these in yellow | T2: VERDICT
A3: # | B3: Date | C3: Team 1 | D3: Team 2 | E3: Venue | F3: Sys Toss Rec | G3: Reason | H3: Top 3 Batters T1 | I3: PP SR T1 | J3: Death SR T1 | K3: Actual Toss Winner ✏ | L3: Toss Decision ✏ | M3: Match Winner ✏ | N3: Margin ✏ | O3: Runs/Wkts ✏ | P3: Biggest Partnership ✏ | Q3: Broken By ✏ | R3: Death Eco (avg) ✏ | S3: Notes / Key Moments ✏ | T3: Toss Correct?
A4: 1 | B4: 2025-04-11 | C4: Lahore Qalandars | D4: Islamabad United | E4: Gaddafi Stadium, Lahore | F4: TOSS-UP | G4: Neutral (chase 41%) | H4: Fakhar Zaman, Muhammad Naeem, Abdullah Shafique | I4: 145.5 | J4: 178.7 | K4: Islamabad United | L4: field | M4: Islamabad United | N4: 4 | O4: wickets | S4: Muhammad Naeem T20 debut | T4: =IF(K4="","",IF(OR(AND(F4="BOWL FIRST",L4="field"),AND(F4="BAT FIRST",L4="bat"),F4="TOSS-UP"),"✓ CORRECT","✗ WRONG"))
A5: 2 | B5: 2025-04-12 | C5: Peshawar Zalmi | D5: Multan Sultans | E5: Rawalpindi Cricket Stadium | F5: TOSS-UP | G5: Neutral (chase 42%) | H5: Saim Ayub, Babar Azam, T Kohler-Cadmore | I5: 120.1 | J5: 166.4 | K5: Peshawar Zalmi | L5: field | M5: Quetta Gladiators | N5: 80 | O5: runs | T5: =IF(K5="","",IF(OR(AND(F5="BOWL FIRST",L5="field"),AND(F5="BAT FIRST",L5="bat"),F5="TOSS-UP"),"✓ CORRECT","✗ WRONG"))
A6: 3 | B6: 2025-04-13 | C6: Multan Sultans | D6: Karachi Kings | E6: National Stadium, Karachi | F6: BOWL FIRST | G6: Dew + chase 60% | H6: Saud Shakeel, FH Allen, RR Rossouw | I6: 155.3 | J6: 166.8 | K6: Karachi Kings | L6: field | M6: Karachi Kings | N6: 4 | O6: wickets | S6: Fawad Ali T20 debut | T6: =IF(K6="","",IF(OR(AND(F6="BOWL FIRST",L6="field"),AND(F6="BAT FIRST",L6="bat"),F6="TOSS-UP"),"✓ CORRECT","✗ WRONG"))
A7: 4 | B7: 2025-04-14 | C7: Islamabad United | D7: Peshawar Zalmi | E7: Rawalpindi Cricket Stadium | F7: TOSS-UP | G7: Neutral (chase 42%) | H7: Sahibzada Farhan, AGS Gous, C Munro | I7: 144.6 | J7: 176.6 | K7: Quetta Gladiators | L7: field | M7: Lahore Qalandars | N7: 79 | O7: runs | T7: =IF(K7="","",IF(OR(AND(F7="BOWL FIRST",L7="field"),AND(F7="BAT FIRST",L7="bat"),F7="TOSS-UP"),"✓ CORRECT","✗ WRONG"))
A8: 5 | B8: 2025-04-15 | C8: Lahore Qalandars | D8: Multan Sultans | E8: Gaddafi Stadium, Lahore | F8: TOSS-UP | G8: Neutral (chase 41%) | H8: Fakhar Zaman, Muhammad Naeem, Abdullah Shafique | I8: 145.5 | J8: 178.7 | K8: Islamabad United | L8: bat | M8: Islamabad United | N8: 102 | O8: runs | T8: =IF(K8="","",IF(OR(AND(F8="BOWL FIRST",L8="field"),AND(F8="BAT FIRST",L8="bat"),F8="TOSS-UP"),"✓ CORRECT","✗ WRONG"))
A9: 6 | B9: 2025-04-16 | C9: Karachi Kings | D9: Islamabad United | E9: National Stadium, Karachi | F9: BOWL FIRST | G9: Dew + chase 60% | H9: TL Seifert, DA Warner, JM Vince | I9: 146.2 | J9: 174.2 | K9: Lahore Qalandars | L9: bat | M9: Lahore Qalandars | N9: 65 | O9: runs | T9: =IF(K9="","",IF(OR(AND(F9="BOWL FIRST",L9="field"),AND(F9="BAT FIRST",L9="bat"),F9="TOSS-UP"),"✓ CORRECT","✗ WRONG"))
A10: 7 | B10: 2025-04-17 | C10: Islamabad United | D10: Multan Sultans | E10: Rawalpindi Cricket Stadium | F10: TOSS-UP | G10: Neutral (chase 42%) | H10: Saim Ayub, Babar Azam, T Kohler-Cadmore | I10: 120.1 | J10: 166.4 | K10: Multan Sultans | L10: field | M10: Karachi Kings | N10: 47 | O10: runs | T10: =IF(K10="","",IF(OR(AND(F10="BOWL FIRST",L10="field"),AND(F10="BAT FIRST",L10="bat"),F10="TOSS-UP"),"✓ CORRECT","✗ WRONG"))
A11: 8 | B11: 2025-04-18 | C11: Multan Sultans | D11: Lahore Qalandars | E11: Multan Cricket Stadium | F11: BAT FIRST | G11: Defend win 62% | H11: Yasir Khan, Mohammad Rizwan, Usman Khan | I11: 134.2 | J11: 161.4 | K11: Karachi Kings | L11: bat | M11: Karachi Kings | N11: 56 | O11: runs | T11: =IF(K11="","",IF(OR(AND(F11="BOWL FIRST",L11="field"),AND(F11="BAT FIRST",L11="bat"),F11="TOSS-UP"),"✓ CORRECT","✗ WRONG"))
A12: 9 | B12: 2025-04-19 | C12: Islamabad United | D12: Quetta Gladiators | E12: Rawalpindi Cricket Stadium | F12: TOSS-UP | G12: Neutral (chase 42%) | H12: Sahibzada Farhan, AGS Gous, C Munro | I12: 144.6 | J12: 176.6 | K12: Peshawar Zalmi | L12: bat | M12: Peshawar Zalmi | N12: 120 | O12: runs | S12: Largest PSL victory by runs ever | T12: =IF(K12="","",IF(OR(AND(F12="BOWL FIRST",L12="field"),AND(F12="BAT FIRST",L12="bat"),F12="TOSS-UP"),"✓ CORRECT","✗ WRONG"))
A13: 10 | B13: 2025-04-20 | C13: Karachi Kings | D13: Peshawar Zalmi | E13: National Stadium, Karachi | F13: BOWL FIRST | G13: Dew + chase 60% | H13: TL Seifert, DA Warner, JM Vince | I13: 146.2 | J13: 174.2 | K13: Islamabad United | L13: field | M13: Quetta Gladiators | N13: 6 | O13: wickets | T13: =IF(K13="","",IF(OR(AND(F13="BOWL FIRST",L13="field"),AND(F13="BAT FIRST",L13="bat"),F13="TOSS-UP"),"✓ CORRECT","✗ WRONG"))
A14: 11 | B14: 2025-04-21 | C14: Multan Sultans | D14: Islamabad United | E14: Multan Cricket Stadium | F14: TOSS-UP | G14: Defend win 62% | H14: Yasir Khan, Mohammad Rizwan, Usman Khan | I14: 134.2 | J14: 161.4 | K14: Karachi Kings | L14: field | M14: Peshawar Zalmi | N14: 2 | O14: wickets | T14: =IF(K14="","",IF(OR(AND(F14="BOWL FIRST",L14="field"),AND(F14="BAT FIRST",L14="bat"),F14="TOSS-UP"),"✓ CORRECT","✗ WRONG"))
A15: 12 | B15: 2025-04-22 | C15: Lahore Qalandars | D15: Quetta Gladiators | E15: Gaddafi Stadium, Lahore | F15: TOSS-UP | G15: Neutral (chase 41%) | H15: Fakhar Zaman, Muhammad Naeem, Abdullah Shafique | I15: 145.5 | J15: 178.7 | K15: Multan Sultans | L15: bat | M15: Multan Sultans | N15: 33 | O15: runs | T15: =IF(K15="","",IF(OR(AND(F15="BOWL FIRST",L15="field"),AND(F15="BAT FIRST",L15="bat"),F15="TOSS-UP"),"✓ CORRECT","✗ WRONG"))
A16: 13 | B16: 2025-04-23 | C16: Peshawar Zalmi | D16: Karachi Kings | E16: Rawalpindi Cricket Stadium | F16: TOSS-UP | G16: Neutral (chase 42%) | H16: Saim Ayub, Babar Azam, T Kohler-Cadmore | I16: 120.1 | J16: 166.4 | K16: Multan Sultans | L16: bat | M16: Quetta Gladiators | N16: 7 | O16: wickets | T16: =IF(K16="","",IF(OR(AND(F16="BOWL FIRST",L16="field"),AND(F16="BAT FIRST",L16="bat"),F16="TOSS-UP"),"✓ CORRECT","✗ WRONG"))
A17: 14 | B17: 2025-04-24 | C17: Islamabad United | D17: Lahore Qalandars | E17: Rawalpindi Cricket Stadium | F17: TOSS-UP | G17: Neutral (chase 42%) | H17: Sahibzada Farhan, AGS Gous, C Munro | I17: 144.6 | J17: 176.6 | K17: Peshawar Zalmi | L17: field | M17: Peshawar Zalmi | N17: 7 | O17: wickets | T17: =IF(K17="","",IF(OR(AND(F17="BOWL FIRST",L17="field"),AND(F17="BAT FIRST",L17="bat"),F17="TOSS-UP"),"✓ CORRECT","✗ WRONG"))
A18: 15 | B18: 2025-04-25 | C18: Quetta Gladiators | D18: Multan Sultans | E18: National Stadium, Karachi | F18: BOWL FIRST | G18: Dew + chase 60% | H18: Saud Shakeel, FH Allen, RR Rossouw | I18: 155.3 | J18: 166.8 | K18: Karachi Kings | L18: field | M18: Karachi Kings | N18: 5 | O18: runs | T18: =IF(K18="","",IF(OR(AND(F18="BOWL FIRST",L18="field"),AND(F18="BAT FIRST",L18="bat"),F18="TOSS-UP"),"✓ CORRECT","✗ WRONG"))
A19: 16 | B19: 2025-04-26 | C19: Karachi Kings | D19: Lahore Qalandars | E19: National Stadium, Karachi | F19: BOWL FIRST | G19: Dew + chase 60% | H19: TL Seifert, DA Warner, JM Vince | I19: 146.2 | J19: 174.2 | K19: Lahore Qalandars | L19: field | M19: Karachi Kings | N19: 5 | O19: wickets | T19: =IF(K19="","",IF(OR(AND(F19="BOWL FIRST",L19="field"),AND(F19="BAT FIRST",L19="bat"),F19="TOSS-UP"),"✓ CORRECT","✗ WRONG"))
A20: 17 | B20: 2025-04-27 | C20: Islamabad United | D20: Multan Sultans | E20: Rawalpindi Cricket Stadium | F20: TOSS-UP | G20: Neutral (chase 42%) | H20: Sahibzada Farhan, AGS Gous, C Munro | I20: 144.6 | J20: 176.6 | K20: Peshawar Zalmi | L20: field | M20: Peshawar Zalmi | N20: 64 | O20: runs | T20: =IF(K20="","",IF(OR(AND(F20="BOWL FIRST",L20="field"),AND(F20="BAT FIRST",L20="bat"),F20="TOSS-UP"),"✓ CORRECT","✗ WRONG"))
A21: 18 | B21: 2025-04-28 | C21: Quetta Gladiators | D21: Peshawar Zalmi | E21: Gaddafi Stadium, Lahore | F21: TOSS-UP | G21: Neutral (chase 41%) | H21: Saud Shakeel, FH Allen, RR Rossouw | I21: 155.3 | J21: 166.8 | K21: Quetta Gladiators | L21: field | M21: Multan Sultans | N21: 10 | O21: wickets | S21: Rizwan first to carry bat in PSL history | T21: =IF(K21="","",IF(OR(AND(F21="BOWL FIRST",L21="field"),AND(F21="BAT FIRST",L21="bat"),F21="TOSS-UP"),"✓ CORRECT","✗ WRONG"))
A22: 19 | B22: 2025-04-29 | C22: Karachi Kings | D22: Multan Sultans | E22: National Stadium, Karachi | F22: BOWL FIRST | G22: Dew + chase 60% | H22: TL Seifert, DA Warner, JM Vince | I22: 146.2 | J22: 174.2 | K22: Islamabad United | L22: field | M22: Islamabad United | N22: 88 | O22: runs | T22: =IF(K22="","",IF(OR(AND(F22="BOWL FIRST",L22="field"),AND(F22="BAT FIRST",L22="bat"),F22="TOSS-UP"),"✓ CORRECT","✗ WRONG"))
A23: 20 | B23: 2025-04-30 | C23: Lahore Qalandars | D23: Peshawar Zalmi | E23: Gaddafi Stadium, Lahore | F23: TOSS-UP | G23: Neutral (chase 41%) | H23: Fakhar Zaman, Muhammad Naeem, Abdullah Shafique | I23: 145.5 | J23: 178.7 | K23: Lahore Qalandars | L23: bat | M23: Peshawar Zalmi | N23: 87 | O23: runs | S23: Toss not in Wikipedia - check scorecard | T23: =IF(K23="","",IF(OR(AND(F23="BOWL FIRST",L23="field"),AND(F23="BAT FIRST",L23="bat"),F23="TOSS-UP"),"✓ CORRECT","✗ WRONG"))
A24: 21 | B24: 2025-05-01 | C24: Islamabad United | D24: Karachi Kings | E24: Rawalpindi Cricket Stadium | F24: TOSS-UP | G24: Neutral (chase 42%) | H24: Sahibzada Farhan, AGS Gous, C Munro | I24: 144.6 | J24: 176.6 | K24: Quetta Gladiators | L24: field | M24: No Result | N24: 0 | O24: NR | S24: Rain - no result after 11.3 overs | T24: =IF(K24="","",IF(OR(AND(F24="BOWL FIRST",L24="field"),AND(F24="BAT FIRST",L24="bat"),F24="TOSS-UP"),"✓ CORRECT","✗ WRONG"))
A25: 22 | B25: 2025-05-02 | C25: Multan Sultans | D25: Quetta Gladiators | E25: Multan Cricket Stadium | F25: BAT FIRST | G25: Defend win 62% | H25: Yasir Khan, Mohammad Rizwan, Usman Khan | I25: 134.2 | J25: 161.4 | K25: Islamabad United | L25: bat | M25: Lahore Qalandars | N25: 6 | O25: wickets | T25: =IF(K25="","",IF(OR(AND(F25="BOWL FIRST",L25="field"),AND(F25="BAT FIRST",L25="bat"),F25="TOSS-UP"),"✓ CORRECT","✗ WRONG"))
A26: 23 | B26: 2025-05-03 | C26: Peshawar Zalmi | D26: Lahore Qalandars | E26: Rawalpindi Cricket Stadium | F26: TOSS-UP | G26: Neutral (chase 42%) | H26: Saim Ayub, Babar Azam, T Kohler-Cadmore | I26: 120.1 | J26: 166.4 | K26: Quetta Gladiators | L26: field | M26: Karachi Kings | N26: 2 | O26: wickets | S26: Quetta qualified for playoffs | T26: =IF(K26="","",IF(OR(AND(F26="BOWL FIRST",L26="field"),AND(F26="BAT FIRST",L26="bat"),F26="TOSS-UP"),"✓ CORRECT","✗ WRONG"))
A27: 24 | B27: 2025-05-04 | C27: Quetta Gladiators | D27: Islamabad United | E27: Gaddafi Stadium, Lahore | F27: TOSS-UP | G27: Neutral (chase 41%) | H27: Saud Shakeel, FH Allen, RR Rossouw | I27: 155.3 | J27: 166.8 | K27: Karachi Kings | L27: field | M27: Peshawar Zalmi | N27: 8 | O27: wickets | S27: Rain - reduced to 15 overs | T27: =IF(K27="","",IF(OR(AND(F27="BOWL FIRST",L27="field"),AND(F27="BAT FIRST",L27="bat"),F27="TOSS-UP"),"✓ CORRECT","✗ WRONG"))
A28: 25 | B28: 2025-05-05 | C28: Multan Sultans | D28: Karachi Kings | E28: Multan Cricket Stadium | F28: BAT FIRST | G28: Defend win 62% | H28: Yasir Khan, Mohammad Rizwan, Usman Khan | I28: 134.2 | J28: 161.4 | K28: Multan Sultans | L28: bat | M28: Lahore Qalandars | N28: 7 | O28: wickets | T28: =IF(K28="","",IF(OR(AND(F28="BOWL FIRST",L28="field"),AND(F28="BAT FIRST",L28="bat"),F28="TOSS-UP"),"✓ CORRECT","✗ WRONG"))
A29: 26 | B29: 2025-05-06 | C29: Lahore Qalandars | D29: Karachi Kings | E29: Gaddafi Stadium, Lahore | F29: TOSS-UP | G29: Neutral (chase 41%) | H29: Fakhar Zaman, Muhammad Naeem, Abdullah Shafique | I29: 145.5 | J29: 178.7 | K29: Islamabad United | L29: field | M29: Islamabad United | N29: 109 | O29: runs | S29: Rossouw+Nawaz centuries - highest PSL total ever 263/3 | T29: =IF(K29="","",IF(OR(AND(F29="BOWL FIRST",L29="field"),AND(F29="BAT FIRST",L29="bat"),F29="TOSS-UP"),"✓ CORRECT","✗ WRONG"))
A30: 27 | B30: 2025-05-07 | C30: Peshawar Zalmi | D30: Islamabad United | E30: Rawalpindi Cricket Stadium | F30: TOSS-UP | G30: Neutral (chase 42%) | H30: Saim Ayub, Babar Azam, T Kohler-Cadmore | I30: 120.1 | J30: 166.4 | K30: Peshawar Zalmi | L30: field | M30: Peshawar Zalmi | N30: 23 | O30: runs | S30: Postponed/resumed after conflict | T30: =IF(K30="","",IF(OR(AND(F30="BOWL FIRST",L30="field"),AND(F30="BAT FIRST",L30="bat"),F30="TOSS-UP"),"✓ CORRECT","✗ WRONG"))
A31: 28 | B31: 2025-05-08 | C31: Quetta Gladiators | D31: Lahore Qalandars | E31: Gaddafi Stadium, Lahore | F31: TOSS-UP | G31: Neutral (chase 41%) | H31: Saud Shakeel, FH Allen, RR Rossouw | I31: 155.3 | J31: 166.8 | K31: Multan Sultans | L31: bat | M31: Lahore Qalandars | N31: 5 | O31: wickets | S31: Lahore qualified | T31: =IF(K31="","",IF(OR(AND(F31="BOWL FIRST",L31="field"),AND(F31="BAT FIRST",L31="bat"),F31="TOSS-UP"),"✓ CORRECT","✗ WRONG"))
A32: 29 | B32: 2025-05-09 | C32: Multan Sultans | D32: Peshawar Zalmi | E32: Multan Cricket Stadium | F32: TOSS-UP | G32: Defend win 62% | H32: Yasir Khan, Mohammad Rizwan, Usman Khan | I32: 134.2 | J32: 161.4 | K32: Peshawar Zalmi | L32: field | M32: Peshawar Zalmi | N32: 26 | O32: runs | S32: Rain 13 overs. Babar 100th PSL. Peshawar elim. | T32: =IF(K32="","",IF(OR(AND(F32="BOWL FIRST",L32="field"),AND(F32="BAT FIRST",L32="bat"),F32="TOSS-UP"),"✓ CORRECT","✗ WRONG"))
A33: 30 | B33: 2025-05-10 | C33: Karachi Kings | D33: Quetta Gladiators | E33: National Stadium, Karachi | F33: BOWL FIRST | G33: Dew + chase 60% | H33: TL Seifert, DA Warner, JM Vince | I33: 146.2 | J33: 174.2 | K33: Karachi Kings | L33: field | M33: Multan Sultans | N33: 79 | O33: runs | T33: =IF(K33="","",IF(OR(AND(F33="BOWL FIRST",L33="field"),AND(F33="BAT FIRST",L33="bat"),F33="TOSS-UP"),"✓ CORRECT","✗ WRONG"))
A34: 31 | B34: 2025-05-13 | C34: Eliminator 1 | D34: Eliminator 2 | E34: Gaddafi Stadium, Lahore | F34: TOSS-UP | G34: Neutral (chase 41%) | H34: -, -, - | I34: - | J34: - | K34: Quetta Gladiators | L34: bat | M34: Quetta Gladiators | N34: 30 | O34: runs | S34: Qualifier - Quetta to final | T34: =IF(K34="","",IF(OR(AND(F34="BOWL FIRST",L34="field"),AND(F34="BAT FIRST",L34="bat"),F34="TOSS-UP"),"✓ CORRECT","✗ WRONG"))
A35: 32 | B35: 2025-05-14 | C35: Qualifier 1 | D35: Qualifier 2 | E35: Gaddafi Stadium, Lahore | F35: TOSS-UP | G35: Neutral (chase 41%) | H35: -, -, - | I35: - | J35: - | K35: Lahore Qalandars | L35: bat | M35: Lahore Qalandars | N35: 95 | O35: runs | S35: Eliminator 1 | T35: =IF(K35="","",IF(OR(AND(F35="BOWL FIRST",L35="field"),AND(F35="BAT FIRST",L35="bat"),F35="TOSS-UP"),"✓ CORRECT","✗ WRONG"))
A36: 33 | B36: 2025-05-16 | C36: Elim Winner | D36: Qualifier Loser | E36: Gaddafi Stadium, Lahore | F36: TOSS-UP | G36: Neutral (chase 41%) | H36: -, -, - | I36: - | J36: - | K36: Karachi Kings | L36: bat | M36: Karachi Kings | N36: 6 | O36: wickets | S36: Eliminator 2 | T36: =IF(K36="","",IF(OR(AND(F36="BOWL FIRST",L36="field"),AND(F36="BAT FIRST",L36="bat"),F36="TOSS-UP"),"✓ CORRECT","✗ WRONG"))
A37: 34 | B37: 2025-05-18 | C37: Finalist 1 | D37: Finalist 2 | E37: Gaddafi Stadium, Lahore | F37: TOSS-UP | G37: Neutral (chase 41%) | H37: -, -, - | I37: - | J37: - | K37: Quetta Gladiators | L37: bat | M37: Lahore Qalandars | N37: 6 | O37: wickets | S37: FINAL - record chase 204/4. Lahore PSL champions | T37: =IF(K37="","",IF(OR(AND(F37="BOWL FIRST",L37="field"),AND(F37="BAT FIRST",L37="bat"),F37="TOSS-UP"),"✓ CORRECT","✗ WRONG"))
A38: SUMMARY | T38: =COUNTIF(T4:T37,"✓ CORRECT")&" / "&COUNTA(T4:T37)&" toss calls correct"
A41: KEY: | K41: GREEN = auto-filled from public sources | P41: YELLOW = needs manual entry from scorecard

Sheet Partnership Back-Test
A1: PARTNERSHIP BACK-TEST | Record the 2-3 biggest partnerships per match and how they ended
A2: MATCH INFO | F2: SYSTEM THRESHOLD (PSL: Critical = 32 balls) | J2: ACTUAL ← fill yellow
A3: Match # | B3: Date | C3: Batting Team | D3: Batter 1 (pre-filled where known) | E3: Batter 2 (pre-filled where known) | F3: System Danger Tier | G3: Balls at Alert | H3: System Breaker Rec | I3: Historical Break Type | J3: Actual Balls Together ✏ | K3: Actual Breaker ✏ | L3: Partnership Runs ✏
A4: 1 | B4: 2025-04-11 | C4: Lahore Qalandars | D4: Abdullah Shafique | E4: Sikandar Raza | F4: CRITICAL if 32+ balls | G4: 32 | H4: Pace (68% avg) | I4: LQ bat
A5: 1 | B5: 2025-04-11 | D5: Colin Munro | E5: Salman Ali Agha | F5: CRITICAL if 32+ balls | G5: 32 | H5: Pace (68% avg) | I5: IU chase — 94 runs unbroken
A6: 1 | B6: 2025-04-11 | D6: Sahibzada Farhan | E6: Colin Munro | F6: CRITICAL if 32+ balls | G6: 32 | H6: Pace (68% avg) | I6: IU 1st wkt
A7: 2 | B7: 2025-04-12 | C7: Peshawar Zalmi | D7: Rilee Rossouw | E7: TBC — check card | F7: CRITICAL if 32+ balls | G7: 32 | H7: Pace (68% avg) | I7: QG bat
A8: 2 | B8: 2025-04-12 | D8: TBC | E8: TBC | F8: CRITICAL if 32+ balls | G8: 32 | H8: Pace (68% avg) | I8: PZ chase
A9: 2 | B9: 2025-04-12 | D9: TBC | E9: TBC | F9: CRITICAL if 32+ balls | G9: 32 | H9: Pace (68% avg) | I9: QG bat #2
A10: 3 | B10: 2025-04-13 | C10: Quetta Gladiators | D10: David Warner | E10: James Vince | F10: CRITICAL if 32+ balls | G10: 32 | H10: Pace (68% avg) | I10: MS/KK bat
A11: 3 | B11: 2025-04-13 | D11: TBC | E11: TBC | F11: CRITICAL if 32+ balls | G11: 32 | H11: Pace (68% avg) | I11: KK chase
A12: 3 | B12: 2025-04-13 | D12: TBC | E12: TBC | F12: CRITICAL if 32+ balls | G12: 32 | H12: Pace (68% avg) | I12: Pace / Spin change
A13: 4 | B13: 2025-04-14 | C13: Islamabad United | D13: TBC | E13: TBC | F13: CRITICAL if 32+ balls | G13: 32 | H13: Pace (68% avg) | I13: LQ bat
A14: 4 | B14: 2025-04-14 | D14: TBC | E14: TBC | F14: CRITICAL if 32+ balls | G14: 32 | H14: Pace (68% avg) | I14: QG chase
A15: 4 | B15: 2025-04-14 | D15: TBC | E15: TBC | F15: CRITICAL if 32+ balls | G15: 32 | H15: Pace (68% avg) | I15: Pace / Spin change
A16: 5 | B16: 2025-04-15 | C16: Lahore Qalandars | D16: Andries Gous | E16: Sahibzada Farhan | F16: CRITICAL if 32+ balls | G16: 32 | H16: Pace (68% avg) | I16: IU bat
A17: 5 | B17: 2025-04-15 | D17: Colin Munro | E17: Salman Ali Agha | F17: CRITICAL if 32+ balls | G17: 32 | H17: Pace (68% avg) | I17: IU bat
A18: 5 | B18: 2025-04-15 | D18: TBC | E18: TBC | F18: CRITICAL if 32+ balls | G18: 32 | H18: Pace (68% avg) | I18: PZ chase
A19: 6 | B19: 2025-04-16 | C19: Karachi Kings | D19: Fakhar Zaman | E19: Abdullah Shafique | F19: CRITICAL if 32+ balls | G19: 32 | H19: Pace (68% avg) | I19: LQ bat
A20: 6 | B20: 2025-04-16 | D20: Muhammad Naeem | E20: Fakhar Zaman | F20: CRITICAL if 32+ balls | G20: 32 | H20: Pace (68% avg) | I20: LQ bat PP
A21: 6 | B21: 2025-04-16 | D21: TBC | E21: TBC | F21: CRITICAL if 32+ balls | G21: 32 | H21: Pace (68% avg) | I21: KK chase
A22: 7 | B22: 2025-04-17 | C22: Peshawar Zalmi | D22: TBC | E22: TBC | F22: CRITICAL if 32+ balls | G22: 32 | H22: Pace (68% avg) | I22: IU bat
A23: 7 | B23: 2025-04-17 | D23: TBC | E23: TBC | F23: CRITICAL if 32+ balls | G23: 32 | H23: Pace (68% avg) | I23: MS chase
A24: 7 | B24: 2025-04-17 | D24: TBC | E24: TBC | F24: CRITICAL if 32+ balls | G24: 32 | H24: Pace (68% avg) | I24: Pace / Spin change
A25: 8 | B25: 2025-04-18 | C25: Multan Sultans | D25: TBC | E25: TBC | F25: CRITICAL if 32+ balls | G25: 32 | H25: Pace (68% avg) | I25: KK bat
A26: 8 | B26: 2025-04-18 | D26: TBC | E26: TBC | F26: CRITICAL if 32+ balls | G26: 32 | H26: Pace (68% avg) | I26: PZ chase
A27: 8 | B27: 2025-04-18 | D27: TBC | E27: TBC | F27: CRITICAL if 32+ balls | G27: 32 | H27: Pace (68% avg) | I27: Pace / Spin change
A28: 9 | B28: 2025-04-19 | C28: Islamabad United | D28: Saim Ayub | E28: Babar Azam | F28: CRITICAL if 32+ balls | G28: 32 | H28: Pace (68% avg) | I28: PZ bat
A29: 9 | B29: 2025-04-19 | D29: TBC | E29: TBC | F29: CRITICAL if 32+ balls | G29: 32 | H29: Pace (68% avg) | I29: MS chase
A30: 9 | B30: 2025-04-19 | D30: TBC | E30: TBC | F30: CRITICAL if 32+ balls | G30: 32 | H30: Pace (68% avg) | I30: Pace / Spin change
A31: 10 | B31: 2025-04-20 | C31: Karachi Kings | D31: TBC | E31: TBC | F31: CRITICAL if 32+ balls | G31: 32 | H31: Pace (68% avg) | I31: KK bat
A32: 10 | B32: 2025-04-20 | D32: TBC | E32: TBC | F32: CRITICAL if 32+ balls | G32: 32 | H32: Pace (68% avg) | I32: IU chase
A33: 10 | B33: 2025-04-20 | D33: TBC | E33: TBC | F33: CRITICAL if 32+ balls | G33: 32 | H33: Pace (68% avg) | I33: Pace / Spin change
A34: 11 | B34: 2025-04-21 | C34: Multan Sultans | D34: TBC | E34: TBC | F34: CRITICAL if 32+ balls | G34: 32 | H34: Pace (68% avg) | I34: PZ bat
A35: 11 | B35: 2025-04-21 | D35: TBC | E35: TBC | F35: CRITICAL if 32+ balls | G35: 32 | H35: Pace (68% avg) | I35: KK chase
A36: 11 | B36: 2025-04-21 | D36: TBC | E36: TBC | F36: CRITICAL if 32+ balls | G36: 32 | H36: Pace (68% avg) | I36: Pace / Spin change
A37: 12 | B37: 2025-04-22 | C37: Lahore Qalandars | D37: Mohammad Rizwan | E37: Yasir Khan | F37: CRITICAL if 32+ balls | G37: 32 | H37: Pace (68% avg) | I37: MS bat — Yasir 87
A38: 12 | B38: 2025-04-22 | D38: Michael Bracewell | E38: Iftikhar Ahmed | F38: CRITICAL if 32+ balls | G38: 32 | H38: Pace (68% avg) | I38: MS bat
A39: 12 | B39: 2025-04-22 | D39: Sikandar Raza | E39: Sam Billings | F39: CRITICAL if 32+ balls | G39: 32 | H39: Pace (68% avg) | I39: LQ chase
A40: 13 | B40: 2025-04-23 | C40: Peshawar Zalmi | D40: Mohammad Rizwan | E40: Yasir Khan | F40: CRITICAL if 32+ balls | G40: 32 | H40: Pace (68% avg) | I40: MS bat
...

Sheet Toss Accuracy
A1: TOSS ACCURACY SUMMARY | Auto-populated from Back-Test Log
A3: METRIC | B3: FORMULA
A4: Total matches entered | B4: =COUNTA('Back-Test Log'!T4:T37)
A5: Toss calls correct | B5: =COUNTIF('Back-Test Log'!T4:T37,"✓ CORRECT")
A6: Toss calls wrong | B6: =COUNTIF('Back-Test Log'!T4:T37,"✗ WRONG")
A7: Accuracy % | B7: =IF(B4=0,"",B5/B4)
A9: BY VENUE | B9: Total
A10: National Stadium, Karachi | B10: =COUNTIFS('Back-Test Log'!E4:E37,"National Stadium, Karachi",'Back-Test Log'!T4:T37,"✓ CORRECT") | C10: =COUNTIF('Back-Test Log'!E4:E37,"National Stadium, Karachi") | D10: =IF(C10=0,"",B10/C10) | E10: Sys: BOWL FIRST
A11: Gaddafi Stadium, Lahore | B11: =COUNTIFS('Back-Test Log'!E4:E37,"Gaddafi Stadium, Lahore",'Back-Test Log'!T4:T37,"✓ CORRECT") | C11: =COUNTIF('Back-Test Log'!E4:E37,"Gaddafi Stadium, Lahore") | D11: =IF(C11=0,"",B11/C11) | E11: Sys: TOSS-UP
A12: Rawalpindi Cricket Stadium | B12: =COUNTIFS('Back-Test Log'!E4:E37,"Rawalpindi Cricket Stadium",'Back-Test Log'!T4:T37,"✓ CORRECT") | C12: =COUNTIF('Back-Test Log'!E4:E37,"Rawalpindi Cricket Stadium") | D12: =IF(C12=0,"",B12/C12) | E12: Sys: TOSS-UP
A13: Multan Cricket Stadium | B13: =COUNTIFS('Back-Test Log'!E4:E37,"Multan Cricket Stadium",'Back-Test Log'!T4:T37,"✓ CORRECT") | C13: =COUNTIF('Back-Test Log'!E4:E37,"Multan Cricket Stadium") | D13: =IF(C13=0,"",B13/C13) | E13: Sys: BAT FIRST

Sheet Instructions
A1: PSL DECISION ENGINE — BACK-TEST INSTRUCTIONS
A3: PURPOSE
B4: Validate whether the system's toss recommendations, partnership danger thresholds,
B5: and key match intelligence align with what actually happened in PSL 2025.
A7: CURRENT STATUS — what is already filled in
A8: K — Toss winner | B8: 34/34 filled automatically from Wikipedia + news sources
A9: L — Toss decision | B9: 34/34 filled automatically from Wikipedia + news sources
A10: M — Match winner | B10: 34/34 filled automatically from Wikipedia
A11: N — Margin | B11: 33/34 filled (match 21 = No Result, margin = 0)
A12: O — Runs or wickets | B12: 33/34 filled (match 21 = NR)
A13: S — Notes | B13: 16/34 filled (key matches: rain, records, milestones)
A14: T — Verdict | B14: FORMULA — calculates automatically from K and L. No input needed.
A16: WHAT YOU STILL NEED TO FILL — 3 yellow columns, all 34 matches
A17: Col P — Biggest partnership | B17: The highest partnership runs in the match (both innings combined).
B18: Go to Cricinfo scorecard → click 'Partnerships' tab → take the largest number shown.
B19: ~30 seconds per match.
A21: Col Q — How was it broken | B21: Type exactly one of: pace spin change run out
B22: Same Partnerships tab. Look at the dismissal — caught off pace = 'pace', spinner/stumped = 'spin', tactical change bowler = 'change', run out = 'run out'.
B23: ~20 seconds per match.
A25: Col R — Death over economy | B25: Average runs per over across overs 17–20 of whichever innings had more death bowling.
B26: Go to 'Ball by Ball' tab on Cricinfo. Add runs in overs 17, 18, 19, 20 and divide by 4. Or check bowler figures for death bowlers and average their economies.
B27: ~60 seconds per match. This column is optional for first-pass analysis.
A29: Col S — Notes (partially filled) | B29: Add anything unusual: dew visible, pitch two-paced, shortened game, key injury, rain interruption.
B30: Only fill matches where something notable happened. 18 matches already have notes.
B31: Optional — only fill if you remember or notice something from the match.
A34: HOW TO ACCESS SCORECARDS ON CRICINFO
A35: Step 1 | B35: Go to: espncricinfo.com/series/pakistan-super-league-2025-1434269/match-schedule-fixtures-and-results
A36: Step 2 | B36: Click any match result to open the scorecard.
A37: Step 3 | B37: For Column P and Q: click the 'Partnerships' tab at the top of the scorecard.
A38: Step 4 | B38: For Column R: click 'Ball by Ball' or 'Over by Over' — find overs 17-20 and add up the runs.
A39: Tip | B39: The scorecard URL pattern is always the same — just change the match number/name at the end for each match.
A40: Fastest method | B40: Open all 34 scorecards as tabs, then go through them one by one filling P, Q, R before closing.
A42: TIME ESTIMATE
A43: Columns K–O, S | B43: Already done. Nothing to enter.
A44: Column P only | B44: ~17 minutes (30 sec × 34 matches)
A45: Columns P + Q | B45: ~27 minutes (50 sec × 34 matches) — recommended minimum
A46: Columns P + Q + R | B46: ~50 minutes (90 sec × 34 matches) — full back-test
A47: Priority order | B47: Do P and Q first. Sheet 3 toss accuracy auto-updates immediately. Partnership threshold check uses P and Q. Death economy (R) is useful but not required for the first calibration run.
A49: AFTER FILLING — what happens next
A50: Sheet 3 auto-updates | B50: Toss Accuracy sheet calculates instantly — overall accuracy % and per-venue breakdown are live the moment you save.
...
